Workbook

Sheet Summarize
B1: SBIR REPORT
B2: Date: | C2: 46298
B4: CONTENT | E4: TOTAL | F4: ='Summarize_team VietNam'!F4 -> 46296 | G4: ='Summarize_team VietNam'!G4 -> 46297 | H4: ='Summarize_team VietNam'!H4 -> 46298 | I4: ='Summarize_team VietNam'!I4 -> 46299 | J4: ='Summarize_team VietNam'!J4 -> 46300 | K4: ='Summarize_team VietNam'!K4 -> 46301 | L4: ='Summarize_team VietNam'!L4 -> 46302 | M4: ='Summarize_team VietNam'!M4 -> 46303 | ... AJ4: ='Summarize_team VietNam'!AJ4 -> 46326
F5: =F4 -> 46296 | G5: =G4 -> 46297 | H5: =H4 -> 46298 | I5: =I4 -> 46299 | J5: =J4 -> 46300 | K5: =K4 -> 46301 | L5: =L4 -> 46302 | M5: =M4 -> 46303 | ... AJ5: =AJ4 -> 46326
B6: Kênh hỗ trợ ①応対チャネル) | C6: Tổng (合計) | E6: =SUM(F6:AJ6) -> 5136 | F6: =SUM(F8:F12) -> 1856 | G6: =SUM(G8:G12) -> 1765 | H6: =SUM(H8:H12) -> 1515 | I6: =SUM(I8:I12) -> 0 | J6: =SUM(J8:J12) -> 0 | K6: =SUM(K8:K12) -> 0 | L6: =SUM(L8:L12) -> 0 | M6: =SUM(M8:M12) -> 0 | ... AJ6: =SUM(AJ8:AJ12) -> 0
C7: ①CUSTOMER | E7: =SUM(F7:AJ7) -> 4232 | F7: ='Summarize_team VietNam'!F11 -> 1540 | G7: ='Summarize_team VietNam'!G11 -> 1437 | H7: ='Summarize_team VietNam'!H11 -> 1255
C8: 1. FACEBOOK (CHAT BOT) | E8: =SUM(F8:AJ8) -> 5012 | F8: ='Summarize_team VietNam'!F12 -> 1796 | G8: ='Summarize_team VietNam'!G12 -> 1722 | H8: ='Summarize_team VietNam'!H12 -> 1494
C9: 2. ZALO | E9: =SUM(F9:AJ9) -> 94 | F9: ='Summarize_team VietNam'!F13 -> 47 | G9: ='Summarize_team VietNam'!G13 -> 29 | H9: ='Summarize_team VietNam'!H13 -> 18
C10: 3. VIBER | E10: =SUM(F10:AJ10) -> 0 | F10: ='Summarize_team VietNam'!F14 -> 0 | G10: ='Summarize_team VietNam'!G14 -> 0 | H10: ='Summarize_team VietNam'!H14 -> 0
C11: 4. LINE | E11: =SUM(F11:AJ11) -> 0 | F11: ='Summarize_team VietNam'!F15 -> 0 | G11: ='Summarize_team VietNam'!G15 -> 0 | H11: ='Summarize_team VietNam'!H15 -> 0
C12: 5. Telephone | E12: =SUM(F12:AJ12) -> 30 | F12: ='Summarize_team VietNam'!F16 -> 13 | G12: ='Summarize_team VietNam'!G16 -> 14 | H12: ='Summarize_team VietNam'!H16 -> 3
C13: ②Unprocessed/未対応 | E13: =SUM(F13:AJ13) -> 67 | F13: ='Summarize_team VietNam'!F17 -> 28 | G13: ='Summarize_team VietNam'!G17 -> 22 | H13: ='Summarize_team VietNam'!H17 -> 17
C14: ② OUTBOUND | E14: =SUM(F14:AJ14) -> 0 | F14: ='Summarize_team VietNam'!F18 -> 0 | G14: ='Summarize_team VietNam'!G18 -> 0 | H14: ='Summarize_team VietNam'!H18 -> 0
B15: ②SALES FORCE 案件 | C15: 合計 (Tổng) | E15: =SUM(F15:AJ15) -> 19215 | F15: =SUM(F16:F24) -> 7552 | G15: =SUM(G16:G24) -> 5918 | H15: =SUM(H16:H24) -> 5745 | I15: =SUM(I16:I24) -> 0 | J15: =SUM(J16:J24) -> 0 | K15: =SUM(K16:K24) -> 0 | L15: =SUM(L16:L24) -> 0 | M15: =SUM(M16:M24) -> 0 | ... AJ15: =SUM(AJ16:AJ24) -> 0
C16: ①『CCVN』team On-processed/処理中 | E16: =SUM(F16:AJ16) -> 3198 | F16: ='Summarize_team VietNam'!F20 -> 1071 | G16: ='Summarize_team VietNam'!G20 -> 1058 | H16: ='Summarize_team VietNam'!H20 -> 1069
C17: ②『CCVN』team Processing request/処理依頼 (BM) | E17: =SUM(F17:AJ17) -> 69 | F17: ='Summarize_team VietNam'!F21 -> 28 | G17: ='Summarize_team VietNam'!G21 -> 22 | H17: ='Summarize_team VietNam'!H21 -> 19
C18: ③『CCVN』team Processing request/処理依頼 (From BO) | E18: =SUM(F18:AJ18) -> 92 | F18: ='Summarize_team VietNam'!F22 -> 32 | G18: ='Summarize_team VietNam'!G22 -> 32 | H18: ='Summarize_team VietNam'!H22 -> 28
C19: ④『CCVN』team Processing request/処理依頼 (From CC-VN) | E19: =SUM(F19:AJ19) -> 528 | F19: ='Summarize_team VietNam'!F23 -> 176 | G19: ='Summarize_team VietNam'!G23 -> 187 | H19: ='Summarize_team VietNam'!H23 -> 165
C20: ⑤『CCVN』team Processing request/処理依頼 (Other) | E20: =SUM(F20:AJ20) -> 181 | F20: ='Summarize_team VietNam'!F24 -> 68 | G20: ='Summarize_team VietNam'!G24 -> 66 | H20: ='Summarize_team VietNam'!H24 -> 47
C21: ⑥『CCVN』team Unprocessed/未処理 | E21: =SUM(F21:AJ21) -> 28 | F21: ='Summarize_team VietNam'!F25 -> 10 | G21: ='Summarize_team VietNam'!G25 -> 15 | H21: ='Summarize_team VietNam'!H25 -> 3
C22: ⑦『CCVN』team waiting-response/連絡待ち | E22: =SUM(F22:AJ22) -> 9371 | F22: ='Summarize_team VietNam'!F26 -> 3131 | G22: ='Summarize_team VietNam'!G26 -> 3121 | H22: ='Summarize_team VietNam'!H26 -> 3119
C23: ⑧『CCVN』team Completed/処理済み | E23: =SUM(F23:AJ23) -> 4107 | F23: ='Summarize_team VietNam'!F27 -> 2466 | G23: ='Summarize_team VietNam'!G27 -> 974 | H23: ='Summarize_team VietNam'!H27 -> 667
C24: ⑨『CCVN』Case check&process/SF案件確認・処理 | E24: =SUM(F24:AJ24) -> 1641 | F24: ='Summarize_team VietNam'!F28 -> 570 | G24: ='Summarize_team VietNam'!G28 -> 443 | H24: ='Summarize_team VietNam'!H28 -> 628
B25: ③Head Count | C25: Order HC(当社が要求しているHC） | E25: =SUM(F25:AJ25) -> 67 | F25: ='Summarize_team VietNam'!F29 -> 22 | G25: ='Summarize_team VietNam'!G29 -> 22 | H25: ='Summarize_team VietNam'!H29 -> 23
C26: Actual HC(実際のHC） | E26: =SUM(F26:AJ26) -> 71 | F26: ='Summarize_team VietNam'!F30 -> 22 | G26: ='Summarize_team VietNam'!G30 -> 24 | H26: ='Summarize_team VietNam'!H30 -> 25
C27: 充足率 | E27: =E26/E25 -> 1.0597015 | F27: ='Summarize_team VietNam'!F31 -> 1 | G27: ='Summarize_team VietNam'!G31 -> 1.0909091 | H27: ='Summarize_team VietNam'!H31 -> 1.0869565 | I27: ='Summarize_team VietNam'!I31 -> 0 | J27: ='Summarize_team VietNam'!J31 -> 0 | K27: ='Summarize_team VietNam'!K31 -> 0 | L27: ='Summarize_team VietNam'!L31 -> 0 | M27: ='Summarize_team VietNam'!M31 -> 0 | ... AJ27: ='Summarize_team VietNam'!AJ31 -> 0

Sheet Summarize_team VietNam
B1: SBIR REPORT
B2: Date: | C2: 46298
B4: CONTENT | E4: TOTAL | F4: 46296 | G4: 46297 | H4: 46298 | I4: 46299 | J4: 46300 | K4: 46301 | L4: 46302 | M4: 46303 | N4: 46304 | O4: 46305 | P4: 46306 | Q4: 46307 | R4: 46308 | S4: 46309 | T4: 46310 | U4: 46311 | V4: 46312 | W4: 46313 | X4: 46314 | Y4: 46315 | Z4: 46316 | AA4: 46317 | AB4: 46318 | AC4: 46319 | AD4: 46320 | AE4: 46321 | AF4: 46322 | AG4: 46323 | AH4: 46324 | AI4: 46325 | AJ4: 46326
F5: =F4 -> 46296 | G5: =G4 -> 46297 | H5: =H4 -> 46298 | I5: =I4 -> 46299 | J5: =J4 -> 46300 | K5: =K4 -> 46301 | L5: =L4 -> 46302 | M5: =M4 -> 46303 | ... AJ5: =AJ4 -> 46326
B6: Đăng ký mới (新規会員登録) | C6: Tổng (合計) | E6: =SUM(F6:AJ6) -> 2 | F6: =SUM(F7:F9) -> 2 | G6: =SUM(G7:G9) -> 0 | H6: =SUM(H7:H9) -> 0 | I6: =SUM(I7:I9) -> 0 | J6: =SUM(J7:J9) -> 0 | K6: =SUM(K7:K9) -> 0 | L6: =SUM(L7:L9) -> 0 | M6: =SUM(M7:M9) -> 0 | ... AJ6: =SUM(AJ7:AJ9) -> 0
C7: ① APP | E7: =SUM(F7:AJ7) -> 2 | F7: 2 | G7: 0 | H7: 0
C8: ② WEBFORM | E8: =SUM(F8:AJ8) -> 0 | F8: 0 | G8: 0 | H8: 0
C9: ③ Kênh khác (CCC) | E9: =SUM(F9:AJ9) -> 0 | F9: 0 | G9: 0 | H9: 0
B10: Kênh hỗ trợ (サポートチャネル) | C10: Tổng (合計) | E10: =SUM(F10:AJ10) -> 5136 | F10: =SUM(F12:F16) -> 1856 | G10: =SUM(G12:G16) -> 1765 | H10: =SUM(H12:H16) -> 1515 | I10: =SUM(I12:I16) -> 0 | J10: =SUM(J12:J16) -> 0 | K10: =SUM(K12:K16) -> 0 | L10: =SUM(L12:L16) -> 0 | M10: =SUM(M12:M16) -> 0 | ... AJ10: =SUM(AJ12:AJ16) -> 0
C11: ①CUSTOMER | E11: =SUM(F11:AJ11) -> 4232 | F11: =1480+SUM(F13:F16) -> 1540 | G11: =1394+SUM(G13:G16) -> 1437 | H11: 1255
C12: 1. FACEBOOK (CHAT BOT) | E12: =SUM(F12:AJ12) -> 5012 | F12: 1796 | G12: 1722 | H12: 1494
C13: 2. ZALO | E13: =SUM(F13:AJ13) -> 94 | F13: 47 | G13: 29 | H13: 18
C14: 3. VIBER | E14: =SUM(F14:AJ14) -> 0 | F14: 0 | G14: 0 | H14: 0
C15: 4. LINE | E15: =SUM(F15:AJ15) -> 0 | F15: 0 | G15: 0 | H15: 0
C16: 5. Telephone | E16: =SUM(F16:AJ16) -> 30 | F16: 13 | G16: 14 | H16: 3
C17: ②Unprocessed/未対応 | E17: =SUM(F17:AJ17) -> 67 | F17: 28 | G17: 22 | H17: 17
C18: ② OUTBOUND | E18: =SUM(F18:AJ18) -> 0 | F18: 0 | G18: 0 | H18: 0
B19: SALES FORCE 案件 | C19: 合計 (Tổng) | E19: =SUM(F19:AJ19) -> 19215 | F19: =SUM(F20:F28) -> 7552 | G19: =SUM(G20:G28) -> 5918 | H19: =SUM(H20:H28) -> 5745 | I19: =SUM(I20:I28) -> 0 | J19: =SUM(J20:J28) -> 0 | K19: =SUM(K20:K28) -> 0 | L19: =SUM(L20:L28) -> 0 | M19: =SUM(M20:M28) -> 0 | ... AJ19: =SUM(AJ20:AJ28) -> 0
C20: ①『CCVN』team On-processed/処理中 | E20: =SUM(F20:AJ20) -> 3198 | F20: 1071 | G20: 1058 | H20: 1069
C21: ②『CCVN』team Processing request/処理依頼 (BM) | E21: =SUM(F21:AJ21) -> 69 | F21: 28 | G21: 22 | H21: 19
C22: ③『CCVN』team Processing request/処理依頼 (From BO) | E22: =SUM(F22:AJ22) -> 92 | F22: 32 | G22: 32 | H22: 28
C23: ④『CCVN』team Processing request/処理依頼 (From CC-VN) | E23: =SUM(F23:AJ23) -> 528 | F23: 176 | G23: 187 | H23: 165
C24: ⑤『CCVN』team Processing request/処理依頼 (Other) | E24: =SUM(F24:AJ24) -> 181 | F24: 68 | G24: 66 | H24: 47
C25: ⑥『CCVN』team Unprocessed/未処理 | E25: =SUM(F25:AJ25) -> 28 | F25: 10 | G25: 15 | H25: 3
C26: ⑦『CCVN』team waiting-response/連絡待ち | E26: =SUM(F26:AJ26) -> 9371 | F26: 3131 | G26: 3121 | H26: 3119
C27: ⑧『CCVN』team Completed/処理済み | E27: =SUM(F27:AJ27) -> 4107 | F27: 2466 | G27: 974 | H27: 667
C28: ⑨『CCVN』Case check&process/SF案件確認・処理 | E28: =SUM(F28:AJ28) -> 1641 | F28: 570 | G28: 443 | H28: 628
B29: ③Head Count | C29: Order HC(当社が要求しているHC） | E29: =SUM(F29:AJ29) -> 67 | F29: 22 | G29: 22 | H29: 23
C30: Actual HC(実際のHC） | E30: =SUM(F30:AJ30) -> 71 | F30: 22 | G30: 24 | H30: 25
C31: 充足率 | E31: =E30/E29 -> 1.0597015 | F31: =F30/F29 -> 1 | G31: =G30/G29 -> 1.0909091 | H31: =H30/H29 -> 1.0869565
B32: Nội dung hỗ trợ (サポート内容) | C32: Tổng (合計） | E32: =SUM(F32:AJ32) -> 6097 | F32: =SUM(F33:F45) -> 2206 | G32: =SUM(G33:G45) -> 1991 | H32: =SUM(H33:H45) -> 1900 | I32: =SUM(I33:I45) -> 0 | J32: =SUM(J33:J45) -> 0 | K32: =SUM(K33:K45) -> 0 | L32: =SUM(L33:L45) -> 0 | M32: =SUM(M33:M45) -> 0 | ... AJ32: =SUM(AJ33:AJ45) -> 0
C33: ① KH Rakuraku đổi sang APP (らくらくからAPP切り替え) | E33: =SUM(F33:AJ33) -> 188 | F33: 44 | G33: 99 | H33: 45
C34: ② Đăng ký mới (新規登録) | E34: =SUM(F34:AJ34) -> 40 | F34: 15 | G34: 17 | H34: 8
C35: ③ Thêm người nhận (受取人追加) | E35: =SUM(F35:AJ35) -> 293 | F35: 94 | G35: 86 | H35: 113
C36: ④ Tình trạng thẻ (カード関連) | E36: =SUM(F36:AJ36) -> 1544 | F36: 502 | G36: 411 | H36: 631
C37: ⑤ Phát hành lại thẻ (カードの再発行) | E37: =SUM(F37:AJ37) -> 72 | F37: 43 | G37: 13 | H37: 16
C38: ⑥ Đổi thông tin thẻ (カード情報変更) | E38: =SUM(F38:AJ38) -> 237 | F38: 80 | G38: 97 | H38: 60
C39: ⑦ Tình trạng giao dịch (送金状況確認) | E39: =SUM(F39:AJ39) -> 444 | F39: 162 | G39: 143 | H39: 139
C40: ⑧ Cập nhật thẻ ngoại kiều (在留カードの更新) | E40: =SUM(F40:AJ40) -> 597 | F40: 185 | G40: 216 | H40: 196
C41: ⑨ Tỷ giá/Lệ phí (手数料等) | E41: =SUM(F41:AJ41) -> 23 | F41: 12 | G41: 4 | H41: 7
...

Sheet 202610 KPI Result
A1: SBIR REPORT_BÁO CÁO KPI TRONG LIVE SUPPORT
A2: 46298
E3: Hiệu suất công việc/稼働率
A4: No | B4: TEAM | C4: OP Name | D4: Email
A5: Leader | E5: 46296 | F5: 46297 | G5: 46298 | H5: 46299 | I5: 46300 | J5: 46301 | K5: 46302 | L5: 46303 | M5: 46304 | N5: 46305 | O5: 46306 | P5: 46307 | Q5: 46308 | R5: 46309 | S5: 46310 | T5: 46311 | U5: 46312 | V5: 46313 | W5: 46314 | X5: 46315 | Y5: 46316 | Z5: 46317 | AA5: 46318 | AB5: 46319 | AC5: 46320 | AD5: 46321 | AE5: 46322 | AF5: 46323 | AG5: 46324 | AH5: 46325 | AI5: 46326
A6: 0 | C6: Dinh Thi Mai Huong | D6: huong.dtm@altius-link.vn
A7: OP | D7: =AVERAGE(E7:AI7) -> 1.2796067 | E7: 1.4708702 | F7: 1.2651918 | G7: 1.1027581
A8: 1 | C8: DINH THI KIM OANH | D8: oanh.dtk@altius-link.vn | E8: 0 | F8: 0 | G8: 0
A9: 2 | C9: PHAM THI THU HOAI | D9: hoai.ptt@altius-link.vn | E9: 0 | F9: 0 | G9: 0
A10: 3 | C10: NGUYEN QUANG HUY | D10: huy.nq1@altius-link.vn | E10: 0 | F10: 0 | G10: 0
A11: 4 | C11: LUU NGOC QUANG | D11: quang.ln@altius-link.com.vn | E11: 0 | F11: 0 | G11: 0
A12: 5 | C12: NGUYEN THUY TRANG | D12: trang.nt@altius-link.com.vn | E12: 0 | F12: 0.91162465 | G12: 1.3453782
A13: 6 | C13: DANG THI BICH | D13: bich.dt@altius-link.com.vn | E13: 0 | F13: 0 | G13: 1.1053221
A14: 7 | C14: NGUYEN THI NGOC THU | D14: thu.ntn@altius-link.com.vn | E14: 1.0969188 | F14: 1.1792717 | G14: 1.2156863
A15: 8 | C15: NGUYEN THI THANH THUY | D15: thuy.ntt1@altius-link.com.vn | E15: 0.95384615 | F15: 1.0383754 | G15: 0.88652154
A16: 9 | C16: TRAN TRUNG DUC | D16: duc.tt@altius-link.com.vn | E16: 1.7014006 | F16: 0 | G16: 0
A17: 10 | C17: NGUYEN TIEN THANG | D17: thang.nt@altius-link.com.vn | E17: 0 | F17: 0 | G17: 0.74660095
A18: 11 | C18: PHUNG LAN HUONG | D18: huong.pl@altius-link.com.vn | E18: 1.0554622 | F18: 1.0431373 | G18: 0.98935574
A19: 12 | C19: LE NGOC THUY | D19: thuy.ln@altius-link.com.vn | E19: 0 | F19: 1.36 | G19: 1.2003676
... A44: 37 | C44: VU HOANG BACH | D44: bach.vh@altius-link.com.vn | E44: 0 | F44: 0.48137255 | G44: 0.59159664
E45: =COUNTIF(E12:E44,">0%") -> 18 | F45: =COUNTIF(F12:F44,">0%") -> 21 | G45: =COUNTIF(G12:G44,">0%") -> 22 | H45: =COUNTIF(H12:H44,">0%") -> 0 | I45: =COUNTIF(I12:I44,">0%") -> 0 | J45: =COUNTIF(J12:J44,">0%") -> 0 | K45: =COUNTIF(K12:K44,">0%") -> 0 | L45: =COUNTIF(L12:L44,">0%") -> 0 | ... AI45: =COUNTIF(AI12:AI44,">0%") -> 0
A46: JP Staff | C46: NGO QUOC BAO | D46: bao.nq@altius-link.com.vn | E46: 1.55 | F46: 0 | G46: 1.13

Sheet Daily KPI Result
A1: SBIR REPORT_BÁO CÁO KPI TRONG LIVE SUPPORT
A2: 46298 | H2: Target/Hour
H3: KH (Lập Case) | I3: 10
H4: KH (Không lập Case) | I4: 15
H5: KH (OB) | I5: 30
H6: Case xử lý | I6: 17
H7: Trả lời comment | I7: 20
E8: =IFERROR(VLOOKUP($D8,#REF!,15,0),0) -> 0 | F8: =IFERROR(VLOOKUP($D8,#REF!,2,0),0) -> 0 | G8: =IF((E8-F8)<0,0,(E8-F8)) -> 0 | H8: =F8*1.5+G8 -> 0 | I8: =IFERROR(VLOOKUP($D8,#REF!,2,0),0) -> 0 | J8: =IFERROR(H8/(I8*15),) -> 0 | K8: =IFERROR(VLOOKUP($D8,#REF!,16,0),0) -> 0 | L8: =IFERROR(VLOOKUP($D8,#REF!,3,0),0) -> 0 | M8: =IFERROR(K8/(L8*30),) -> 0 | N8: =IFERROR(VLOOKUP($D8,#REF!,17,0),0) -> 0 | O8: =IFERROR(VLOOKUP($D8,#REF!,4,0),0) -> 0 | P8: =IFERROR(N8/(O8*17),) -> 0 | Q8: =IFERROR(VLOOKUP($D8,#REF!,18,0),0) -> 0 | R8: =IFERROR(VLOOKUP($D8,#REF!,5,0),0) -> 0 | S8: =IFERROR(Q8/(R8*20),) -> 0 | T8: =IFERROR(VLOOKUP($D8,#REF!,19,0),0) -> 0 | W8: =IFERROR((J8*I8+M8*L8+P8*O8+S8*R8+#REF!*#REF!)/SUM(I8,L8,O8,R8,#REF!),0) -> 0
E9: CSKH | K9: OUTBOUND | N9: XỬ LÝ CASE | Q9: TRẢ LỜI COMMENT | T9: ĐKM + Webform+Gọi Bank
A10: No | B10: Team | C10: Name | D10: Email | E10: Tổng KH Hỗ trợ | F10: Tổng KH (Lập Case) | G10: Tổng KH (không lập Case) | H10: Tổng Yêu cầu (Tính KPI) (Quy về 15KH/h) | I10: Tổng số giờ đã hỗ trợ KH | J10: Hiệu suất công việc | K10: Tổng số KH OB | L10: Tổng số giờ đã OB | M10: Hiệu suất công việc | N10: Tổng số case xử lý | O10: Tổng số giờ đã xử lý case | P10: Hiệu suất công việc | Q10: Tổng số comment trả lời | R10: Tổng số giờ đã trả lời comment | S10: Hiệu suất công việc | T10: Tổng số lượng xử lý | U10: Tổng số giờ đã xử lý | V10: Hiệu suất công việc | W10: Hiệu suất công việc
E11: A=Sheet CSKH (1) (Trừ Outbound/ Xử lý Case) | F11: B=Sheet SF (2) | G11: C=A-B | H11: D=B*1,5 + C | I11: E | J11: X | K11: F (Sheet (1) Phần Outbound) | L11: G | M11: Y | N11: H (Sheet (1) Phần số Case xử lý) | O11: I | P11: Z | Q11: H (Sheet (1) Phần số Case xử lý) | R11: I | S11: Z | W11: (Ex X+GxY+I)/(E+G+I)
A12: Leader
A13: 0 | C13: Dinh Thi Mai Huong | D13: huong.dtm@altius-link.vn | E13: =IFERROR(VLOOKUP($D13,#REF!,9,0),"")
A14: OP | E14: =SUM(E15:E42) -> 1175 | F14: =SUM(F15:F42) -> 262 | G14: =IF((E14-F14)<0,0,(E14-F14)) -> 913 | H14: =F14*1.5+G14 -> 1306 | I14: =SUM(I15:I42) -> 81.017647 | J14: =(H14/(I14*15)) -> 1.074663 | K14: =SUM(K15:K42) -> 0 | L14: =SUM(L15:L42) -> 0 | M14: =IFERROR(K14/(L14*30),0) -> 0 | N14: =SUM(N15:N42) -> 470 | O14: =SUM(O15:O42) -> 22.983431 | P14: =IFERROR(N14/(O14*17),) -> 1.2029126 | Q14: =SUM(Q15:Q42) -> 5 | R14: =SUM(R15:R42) -> 0.25 | S14: =IFERROR(Q14/(R14*20),) -> 1 | T14: =SUM(T15:T42) -> 0 | U14: =SUM(U15:U42) -> 0 | V14: =IFERROR(T14/(U14*20),) -> 0 | W14: =IFERROR((J14*I14+M14*L14+P14*O14+S14*R14+V14*U14)/SUM(I14,L14,O14,R14,U14),0) -> 1.1027581
A15: 1 | C15: DINH THI KIM OANH | D15: oanh.dtk@altius-link.vn | E15: =IFERROR(VLOOKUP($D15,Sheet5!$A$2:$S$73,15,0),"") | F15: =IFERROR(VLOOKUP($D15,Sheet5!$A$74:$B$132,2,0),"") | G15: =IFERROR(IF((E15-F15)<0,0,(E15-F15)),"") | H15: =IFERROR(F15*1.5+G15,"") | I15: =IFERROR(VLOOKUP($D15,Sheet5!$A$167:$F$221,2,0),0) -> 0 | J15: =IFERROR(H15/(I15*15),) -> 0 | K15: =IFERROR(VLOOKUP($D15,Sheet5!$A$2:$S$61,16,0),"") | L15: =IFERROR(VLOOKUP($D15,Sheet5!$A$167:$F$221,3,0),0) -> 0 | M15: =IFERROR(K15/(L15*30),0) -> 0 | N15: =IFERROR(VLOOKUP($D15,Sheet5!$A$2:$S$71,17,0),"") | O15: =IFERROR(VLOOKUP($D15,Sheet5!$A$167:$F$221,4,0),0) -> 0 | P15: =IFERROR(N15/(O15*17),) -> 0 | Q15: =IFERROR(VLOOKUP($D15,Sheet5!$A$2:$S$73,18,0),"") | R15: =IFERROR(VLOOKUP($D15,Sheet5!$A$167:$F$210,5,0),0) -> 0 | S15: =IFERROR(Q15/(R15*20),) -> 0 | T15: =IFERROR(VLOOKUP($D15,Sheet5!$A$2:$S$73,19,0),"") | U15: =IFERROR(VLOOKUP($D15,Sheet5!$A$167:$F$200,6,0),0) -> 0 | V15: =IFERROR(T15/(U15*20),) -> 0 | W15: =IFERROR((J15*I15+M15*L15+P15*O15+S15*R15+V15*U15)/SUM(I15,L15,O15,R15,U15),0) -> 0
A16: 2 | C16: PHAM THI THU HOAI | D16: hoai.ptt@altius-link.vn | E16: =IFERROR(VLOOKUP($D16,Sheet5!$A$2:$S$73,15,0),"") -> 11 | F16: =IFERROR(VLOOKUP($D16,Sheet5!$A$74:$B$132,2,0),"") -> 7 | G16: =IFERROR(IF((E16-F16)<0,0,(E16-F16)),"") -> 4 | H16: =IFERROR(F16*1.5+G16,"") -> 14.5 | I16: =IFERROR(VLOOKUP($D16,Sheet5!$A$167:$F$221,2,0),0) -> 0 | J16: =IFERROR(H16/(I16*15),) -> 0 | K16: =IFERROR(VLOOKUP($D16,Sheet5!$A$2:$S$61,16,0),"") -> 0 | L16: =IFERROR(VLOOKUP($D16,Sheet5!$A$167:$F$221,3,0),0) -> 0 | M16: =IFERROR(K16/(L16*30),0) -> 0 | N16: =IFERROR(VLOOKUP($D16,Sheet5!$A$2:$S$71,17,0),"") -> 0 | O16: =IFERROR(VLOOKUP($D16,Sheet5!$A$167:$F$221,4,0),0) -> 0 | P16: =IFERROR(N16/(O16*17),) -> 0 | Q16: =IFERROR(VLOOKUP($D16,Sheet5!$A$2:$S$73,18,0),"") -> 0 | R16: =IFERROR(VLOOKUP($D16,Sheet5!$A$167:$F$210,5,0),0) -> 0 | S16: =IFERROR(Q16/(R16*20),) -> 0 | T16: =IFERROR(VLOOKUP($D16,Sheet5!$A$2:$S$73,19,0),"") -> 0 | U16: =IFERROR(VLOOKUP($D16,Sheet5!$A$167:$F$200,6,0),0) -> 0 | V16: =IFERROR(T16/(U16*20),) -> 0 | W16: =IFERROR((J16*I16+M16*L16+P16*O16+S16*R16+V16*U16)/SUM(I16,L16,O16,R16,U16),0) -> 0
A17: 3 | C17: NGUYEN QUANG HUY | D17: huy.nq1@altius-link.vn | E17: =IFERROR(VLOOKUP($D17,Sheet5!$A$2:$S$73,15,0),"") | F17: =IFERROR(VLOOKUP($D17,Sheet5!$A$74:$B$132,2,0),"") | G17: =IFERROR(IF((E17-F17)<0,0,(E17-F17)),"") | H17: =IFERROR(F17*1.5+G17,"") | I17: =IFERROR(VLOOKUP($D17,Sheet5!$A$167:$F$221,2,0),0) -> 0 | J17: =IFERROR(H17/(I17*15),) -> 0 | K17: =IFERROR(VLOOKUP($D17,Sheet5!$A$2:$S$61,16,0),"") | L17: =IFERROR(VLOOKUP($D17,Sheet5!$A$167:$F$221,3,0),0) -> 0 | M17: =IFERROR(K17/(L17*30),0) -> 0 | N17: =IFERROR(VLOOKUP($D17,Sheet5!$A$2:$S$71,17,0),"") | O17: =IFERROR(VLOOKUP($D17,Sheet5!$A$167:$F$221,4,0),0) -> 0 | P17: =IFERROR(N17/(O17*17),) -> 0 | Q17: =IFERROR(VLOOKUP($D17,Sheet5!$A$2:$S$73,18,0),"") | R17: =IFERROR(VLOOKUP($D17,Sheet5!$A$167:$F$210,5,0),0) -> 0 | S17: =IFERROR(Q17/(R17*20),) -> 0 | T17: =IFERROR(VLOOKUP($D17,Sheet5!$A$2:$S$73,19,0),"") | U17: =IFERROR(VLOOKUP($D17,Sheet5!$A$167:$F$200,6,0),0) -> 0 | V17: =IFERROR(T17/(U17*20),) -> 0 | W17: =IFERROR((J17*I17+M17*L17+P17*O17+S17*R17+V17*U17)/SUM(I17,L17,O17,R17,U17),0) -> 0
A18: 4 | C18: LUU NGOC QUANG | D18: quang.ln@altius-link.com.vn | E18: =IFERROR(VLOOKUP($D18,Sheet5!$A$2:$S$73,15,0),"") -> 10 | F18: =IFERROR(VLOOKUP($D18,Sheet5!$A$74:$B$132,2,0),"") -> 2 | G18: =IFERROR(IF((E18-F18)<0,0,(E18-F18)),"") -> 8 | H18: =IFERROR(F18*1.5+G18,"") -> 11 | I18: =IFERROR(VLOOKUP($D18,Sheet5!$A$167:$F$221,2,0),0) -> 0 | J18: =IFERROR(H18/(I18*15),) -> 0 | K18: =IFERROR(VLOOKUP($D18,Sheet5!$A$2:$S$61,16,0),"") -> 0 | L18: =IFERROR(VLOOKUP($D18,Sheet5!$A$167:$F$221,3,0),0) -> 0 | M18: =IFERROR(K18/(L18*30),0) -> 0 | N18: =IFERROR(VLOOKUP($D18,Sheet5!$A$2:$S$71,17,0),"") -> 0 | O18: =IFERROR(VLOOKUP($D18,Sheet5!$A$167:$F$221,4,0),0) -> 0 | P18: =IFERROR(N18/(O18*17),) -> 0 | Q18: =IFERROR(VLOOKUP($D18,Sheet5!$A$2:$S$73,18,0),"") -> 0 | R18: =IFERROR(VLOOKUP($D18,Sheet5!$A$167:$F$210,5,0),0) -> 0 | S18: =IFERROR(Q18/(R18*20),) -> 0 | T18: =IFERROR(VLOOKUP($D18,Sheet5!$A$2:$S$73,19,0),"") -> 0 | U18: =IFERROR(VLOOKUP($D18,Sheet5!$A$167:$F$200,6,0),0) -> 0 | V18: =IFERROR(T18/(U18*20),) -> 0 | W18: =IFERROR((J18*I18+M18*L18+P18*O18+S18*R18+V18*U18)/SUM(I18,L18,O18,R18,U18),0) -> 0
A19: 5 | C19: NGUYEN THUY TRANG | D19: trang.nt@altius-link.com.vn | E19: =IFERROR(VLOOKUP($D19,Sheet5!$A$2:$S$73,15,0),"") -> 66 | F19: =IFERROR(VLOOKUP($D19,Sheet5!$A$74:$B$132,2,0),"") -> 27 | G19: =IFERROR(IF((E19-F19)<0,0,(E19-F19)),"") -> 39 | H19: =IFERROR(F19*1.5+G19,"") -> 79.5 | I19: =IFERROR(VLOOKUP($D19,Sheet5!$A$167:$F$221,2,0),0) -> 3.5 | J19: =IFERROR(H19/(I19*15),) -> 1.5142857 | K19: =IFERROR(VLOOKUP($D19,Sheet5!$A$2:$S$61,16,0),"") -> 0 | L19: =IFERROR(VLOOKUP($D19,Sheet5!$A$167:$F$221,3,0),0) -> 0 | M19: =IFERROR(K19/(L19*30),0) -> 0 | N19: =IFERROR(VLOOKUP($D19,Sheet5!$A$2:$S$71,17,0),"") -> 70 | O19: =IFERROR(VLOOKUP($D19,Sheet5!$A$167:$F$221,4,0),0) -> 3.5 | P19: =IFERROR(N19/(O19*17),) -> 1.1764706 | Q19: =IFERROR(VLOOKUP($D19,Sheet5!$A$2:$S$73,18,0),"") -> 0 | R19: =IFERROR(VLOOKUP($D19,Sheet5!$A$167:$F$210,5,0),0) -> 0 | S19: =IFERROR(Q19/(R19*20),) -> 0 | T19: =IFERROR(VLOOKUP($D19,Sheet5!$A$2:$S$73,19,0),"") -> 0 | U19: =IFERROR(VLOOKUP($D19,Sheet5!$A$167:$F$200,6,0),0) -> 0 | V19: =IFERROR(T19/(U19*20),) -> 0 | W19: =IFERROR((J19*I19+M19*L19+P19*O19+S19*R19+V19*U19)/SUM(I19,L19,O19,R19,U19),0) -> 1.3453782
A20: 6 | C20: DANG THI BICH | D20: bich.dt@altius-link.com.vn | E20: =IFERROR(VLOOKUP($D20,Sheet5!$A$2:$S$73,15,0),"") -> 101 | F20: =IFERROR(VLOOKUP($D20,Sheet5!$A$74:$B$132,2,0),"") -> 16 | G20: =IFERROR(IF((E20-F20)<0,0,(E20-F20)),"") -> 85 | H20: =IFERROR(F20*1.5+G20,"") -> 109 | I20: =IFERROR(VLOOKUP($D20,Sheet5!$A$167:$F$221,2,0),0) -> 6.7 | J20: =IFERROR(H20/(I20*15),) -> 1.0845771 | K20: =IFERROR(VLOOKUP($D20,Sheet5!$A$2:$S$61,16,0),"") -> 0 | L20: =IFERROR(VLOOKUP($D20,Sheet5!$A$167:$F$221,3,0),0) -> 0 | M20: =IFERROR(K20/(L20*30),0) -> 0 | N20: =IFERROR(VLOOKUP($D20,Sheet5!$A$2:$S$71,17,0),"") -> 8 | O20: =IFERROR(VLOOKUP($D20,Sheet5!$A$167:$F$221,4,0),0) -> 0.3 | P20: =IFERROR(N20/(O20*17),) -> 1.5686275 | Q20: =IFERROR(VLOOKUP($D20,Sheet5!$A$2:$S$73,18,0),"") -> 0 | R20: =IFERROR(VLOOKUP($D20,Sheet5!$A$167:$F$210,5,0),0) -> 0 | S20: =IFERROR(Q20/(R20*20),) -> 0 | T20: =IFERROR(VLOOKUP($D20,Sheet5!$A$2:$S$73,19,0),"") -> 0 | U20: =IFERROR(VLOOKUP($D20,Sheet5!$A$167:$F$200,6,0),0) -> 0 | V20: =IFERROR(T20/(U20*20),) -> 0 | W20: =IFERROR((J20*I20+M20*L20+P20*O20+S20*R20+V20*U20)/SUM(I20,L20,O20,R20,U20),0) -> 1.1053221
A21: 7 | C21: NGUYEN THI NGOC THU | D21: thu.ntn@altius-link.com.vn | E21: =IFERROR(VLOOKUP($D21,Sheet5!$A$2:$S$73,15,0),"") -> 51 | F21: =IFERROR(VLOOKUP($D21,Sheet5!$A$74:$B$132,2,0),"") -> 8 | G21: =IFERROR(IF((E21-F21)<0,0,(E21-F21)),"") -> 43 | H21: =IFERROR(F21*1.5+G21,"") -> 55 | I21: =IFERROR(VLOOKUP($D21,Sheet5!$A$167:$F$221,2,0),0) -> 3 | J21: =IFERROR(H21/(I21*15),) -> 1.2222222 | K21: =IFERROR(VLOOKUP($D21,Sheet5!$A$2:$S$61,16,0),"") -> 0 | L21: =IFERROR(VLOOKUP($D21,Sheet5!$A$167:$F$221,3,0),0) -> 0 | M21: =IFERROR(K21/(L21*30),0) -> 0 | N21: =IFERROR(VLOOKUP($D21,Sheet5!$A$2:$S$71,17,0),"") -> 10 | O21: =IFERROR(VLOOKUP($D21,Sheet5!$A$167:$F$221,4,0),0) -> 0.5 | P21: =IFERROR(N21/(O21*17),) -> 1.1764706 | Q21: =IFERROR(VLOOKUP($D21,Sheet5!$A$2:$S$73,18,0),"") -> 0 | R21: =IFERROR(VLOOKUP($D21,Sheet5!$A$167:$F$210,5,0),0) -> 0 | S21: =IFERROR(Q21/(R21*20),) -> 0 | T21: =IFERROR(VLOOKUP($D21,Sheet5!$A$2:$S$73,19,0),"") -> 0 | U21: =IFERROR(VLOOKUP($D21,Sheet5!$A$167:$F$200,6,0),0) -> 0 | V21: =IFERROR(T21/(U21*20),) -> 0 | W21: =IFERROR((J21*I21+M21*L21+P21*O21+S21*R21+V21*U21)/SUM(I21,L21,O21,R21,U21),0) -> 1.2156863
A22: 8 | C22: NGUYEN THI THANH THUY | D22: thuy.ntt1@altius-link.com.vn | E22: =IFERROR(VLOOKUP($D22,Sheet5!$A$2:$S$73,15,0),"") -> 55 | F22: =IFERROR(VLOOKUP($D22,Sheet5!$A$74:$B$132,2,0),"") -> 13 | G22: =IFERROR(IF((E22-F22)<0,0,(E22-F22)),"") -> 42 | H22: =IFERROR(F22*1.5+G22,"") -> 61.5 | I22: =IFERROR(VLOOKUP($D22,Sheet5!$A$167:$F$221,2,0),0) -> 4.75 | J22: =IFERROR(H22/(I22*15),) -> 0.86315789 | K22: =IFERROR(VLOOKUP($D22,Sheet5!$A$2:$S$61,16,0),"") -> 0 | L22: =IFERROR(VLOOKUP($D22,Sheet5!$A$167:$F$221,3,0),0) -> 0 | M22: =IFERROR(K22/(L22*30),0) -> 0 | N22: =IFERROR(VLOOKUP($D22,Sheet5!$A$2:$S$71,17,0),"") -> 26 | O22: =IFERROR(VLOOKUP($D22,Sheet5!$A$167:$F$221,4,0),0) -> 1.6 | P22: =IFERROR(N22/(O22*17),) -> 0.95588235 | Q22: =IFERROR(VLOOKUP($D22,Sheet5!$A$2:$S$73,18,0),"") -> 0 | R22: =IFERROR(VLOOKUP($D22,Sheet5!$A$167:$F$210,5,0),0) -> 0 | S22: =IFERROR(Q22/(R22*20),) -> 0 | T22: =IFERROR(VLOOKUP($D22,Sheet5!$A$2:$S$73,19,0),"") -> 0 | U22: =IFERROR(VLOOKUP($D22,Sheet5!$A$167:$F$200,6,0),0) -> 0 | V22: =IFERROR(T22/(U22*20),) -> 0 | W22: =IFERROR((J22*I22+M22*L22+P22*O22+S22*R22+V22*U22)/SUM(I22,L22,O22,R22,U22),0) -> 0.88652154
A23: 9 | C23: TRAN TRUNG DUC | D23: duc.tt@altius-link.com.vn | E23: =IFERROR(VLOOKUP($D23,Sheet5!$A$2:$S$73,15,0),"") | F23: =IFERROR(VLOOKUP($D23,Sheet5!$A$74:$B$132,2,0),"") | G23: =IFERROR(IF((E23-F23)<0,0,(E23-F23)),"") | H23: =IFERROR(F23*1.5+G23,"") | I23: =IFERROR(VLOOKUP($D23,Sheet5!$A$167:$F$221,2,0),0) -> 0 | J23: =IFERROR(H23/(I23*15),) -> 0 | K23: =IFERROR(VLOOKUP($D23,Sheet5!$A$2:$S$61,16,0),"") | L23: =IFERROR(VLOOKUP($D23,Sheet5!$A$167:$F$221,3,0),0) -> 0 | M23: =IFERROR(K23/(L23*30),0) -> 0 | N23: =IFERROR(VLOOKUP($D23,Sheet5!$A$2:$S$71,17,0),"") | O23: =IFERROR(VLOOKUP($D23,Sheet5!$A$167:$F$221,4,0),0) -> 0 | P23: =IFERROR(N23/(O23*17),) -> 0 | Q23: =IFERROR(VLOOKUP($D23,Sheet5!$A$2:$S$73,18,0),"") | R23: =IFERROR(VLOOKUP($D23,Sheet5!$A$167:$F$210,5,0),0) -> 0 | S23: =IFERROR(Q23/(R23*20),) -> 0 | T23: =IFERROR(VLOOKUP($D23,Sheet5!$A$2:$S$73,19,0),"") | U23: =IFERROR(VLOOKUP($D23,Sheet5!$A$167:$F$200,6,0),0) -> 0 | V23: =IFERROR(T23/(U23*20),) -> 0 | W23: =IFERROR((J23*I23+M23*L23+P23*O23+S23*R23+V23*U23)/SUM(I23,L23,O23,R23,U23),0) -> 0
A24: 10 | C24: NGUYEN TIEN THANG | D24: thang.nt@altius-link.com.vn | E24: =IFERROR(VLOOKUP($D24,Sheet5!$A$2:$S$73,15,0),"") -> 70 | F24: =IFERROR(VLOOKUP($D24,Sheet5!$A$74:$B$132,2,0),"") -> 8 | G24: =IFERROR(IF((E24-F24)<0,0,(E24-F24)),"") -> 62 | H24: =IFERROR(F24*1.5+G24,"") -> 74 | I24: =IFERROR(VLOOKUP($D24,Sheet5!$A$167:$F$221,2,0),0) -> 6.71 | J24: =IFERROR(H24/(I24*15),) -> 0.73522106 | K24: =IFERROR(VLOOKUP($D24,Sheet5!$A$2:$S$61,16,0),"") -> 0 | L24: =IFERROR(VLOOKUP($D24,Sheet5!$A$167:$F$221,3,0),0) -> 0 | M24: =IFERROR(K24/(L24*30),0) -> 0 | N24: =IFERROR(VLOOKUP($D24,Sheet5!$A$2:$S$71,17,0),"") -> 5 | O24: =IFERROR(VLOOKUP($D24,Sheet5!$A$167:$F$221,4,0),0) -> 0.29166667 | P24: =IFERROR(N24/(O24*17),) -> 1.0084034 | Q24: =IFERROR(VLOOKUP($D24,Sheet5!$A$2:$S$73,18,0),"") -> 0 | R24: =IFERROR(VLOOKUP($D24,Sheet5!$A$167:$F$210,5,0),0) -> 0 | S24: =IFERROR(Q24/(R24*20),) -> 0 | T24: =IFERROR(VLOOKUP($D24,Sheet5!$A$2:$S$73,19,0),"") -> 0 | U24: =IFERROR(VLOOKUP($D24,Sheet5!$A$167:$F$200,6,0),0) -> 0 | V24: =IFERROR(T24/(U24*20),) -> 0 | W24: =IFERROR((J24*I24+M24*L24+P24*O24+S24*R24+V24*U24)/SUM(I24,L24,O24,R24,U24),0) -> 0.74660095
A25: 11 | C25: PHUNG LAN HUONG | D25: huong.pl@altius-link.com.vn | E25: =IFERROR(VLOOKUP($D25,Sheet5!$A$2:$S$73,15,0),"") -> 60 | F25: =IFERROR(VLOOKUP($D25,Sheet5!$A$74:$B$132,2,0),"") -> 26 | G25: =IFERROR(IF((E25-F25)<0,0,(E25-F25)),"") -> 34 | H25: =IFERROR(F25*1.5+G25,"") -> 73 | I25: =IFERROR(VLOOKUP($D25,Sheet5!$A$167:$F$221,2,0),0) -> 5 | J25: =IFERROR(H25/(I25*15),) -> 0.97333333 | K25: =IFERROR(VLOOKUP($D25,Sheet5!$A$2:$S$61,16,0),"") -> 0 | L25: =IFERROR(VLOOKUP($D25,Sheet5!$A$167:$F$221,3,0),0) -> 0 | M25: =IFERROR(K25/(L25*30),0) -> 0 | N25: =IFERROR(VLOOKUP($D25,Sheet5!$A$2:$S$71,17,0),"") -> 35 | O25: =IFERROR(VLOOKUP($D25,Sheet5!$A$167:$F$221,4,0),0) -> 2 | P25: =IFERROR(N25/(O25*17),) -> 1.0294118 | Q25: =IFERROR(VLOOKUP($D25,Sheet5!$A$2:$S$73,18,0),"") -> 0 | R25: =IFERROR(VLOOKUP($D25,Sheet5!$A$167:$F$210,5,0),0) -> 0 | S25: =IFERROR(Q25/(R25*20),) -> 0 | T25: =IFERROR(VLOOKUP($D25,Sheet5!$A$2:$S$73,19,0),"") -> 0 | U25: =IFERROR(VLOOKUP($D25,Sheet5!$A$167:$F$200,6,0),0) -> 0 | V25: =IFERROR(T25/(U25*20),) -> 0 | W25: =IFERROR((J25*I25+M25*L25+P25*O25+S25*R25+V25*U25)/SUM(I25,L25,O25,R25,U25),0) -> 0.98935574
A26: 12 | C26: LE NGOC THUY | D26: thuy.ln@altius-link.com.vn | E26: =IFERROR(VLOOKUP($D26,Sheet5!$A$2:$S$73,15,0),"") -> 81 | F26: =IFERROR(VLOOKUP($D26,Sheet5!$A$74:$B$132,2,0),"") -> 12 | G26: =IFERROR(IF((E26-F26)<0,0,(E26-F26)),"") -> 69 | H26: =IFERROR(F26*1.5+G26,"") -> 87 | I26: =IFERROR(VLOOKUP($D26,Sheet5!$A$167:$F$221,2,0),0) -> 4.5176471 | J26: =IFERROR(H26/(I26*15),) -> 1.2838542 | K26: =IFERROR(VLOOKUP($D26,Sheet5!$A$2:$S$61,16,0),"") -> 0 | L26: =IFERROR(VLOOKUP($D26,Sheet5!$A$167:$F$221,3,0),0) -> 0 | M26: =IFERROR(K26/(L26*30),0) -> 0 | N26: =IFERROR(VLOOKUP($D26,Sheet5!$A$2:$S$71,17,0),"") -> 32 | O26: =IFERROR(VLOOKUP($D26,Sheet5!$A$167:$F$221,4,0),0) -> 1.8823529 | P26: =IFERROR(N26/(O26*17),) -> 1 | Q26: =IFERROR(VLOOKUP($D26,Sheet5!$A$2:$S$73,18,0),"") -> 0 | R26: =IFERROR(VLOOKUP($D26,Sheet5!$A$167:$F$210,5,0),0) -> 0 | S26: =IFERROR(Q26/(R26*20),) -> 0 | T26: =IFERROR(VLOOKUP($D26,Sheet5!$A$2:$S$73,19,0),"") -> 0 | U26: =IFERROR(VLOOKUP($D26,Sheet5!$A$167:$F$200,6,0),0) -> 0 | V26: =IFERROR(T26/(U26*20),) -> 0 | W26: =IFERROR((J26*I26+M26*L26+P26*O26+S26*R26+V26*U26)/SUM(I26,L26,O26,R26,U26),0) -> 1.2003676
... A51: 37 | C51: VU HOANG BACH | D51: bach.vh@altius-link.com.vn | E51: =IFERROR(VLOOKUP($D51,Sheet5!$A$2:$S$73,15,0),"") -> 42 | F51: =IFERROR(VLOOKUP($D51,Sheet5!$A$74:$B$132,2,0),"") -> 12 | G51: =IFERROR(IF((E51-F51)<0,0,(E51-F51)),"") -> 30 | H51: =IFERROR(F51*1.5+G51,"") -> 48 | I51: =IFERROR(VLOOKUP($D51,Sheet5!$A$167:$F$221,2,0),0) -> 6 | J51: =IFERROR(H51/(I51*15),) -> 0.53333333 | K51: =IFERROR(VLOOKUP($D51,Sheet5!$A$2:$S$61,16,0),"") -> 0 | L51: =IFERROR(VLOOKUP($D51,Sheet5!$A$167:$F$221,3,0),0) -> 0 | M51: =IFERROR(K51/(L51*30),0) -> 0 | N51: =IFERROR(VLOOKUP($D51,Sheet5!$A$2:$S$71,17,0),"") -> 16 | O51: =IFERROR(VLOOKUP($D51,Sheet5!$A$167:$F$221,4,0),0) -> 1 | P51: =IFERROR(N51/(O51*17),) -> 0.94117647 | Q51: =IFERROR(VLOOKUP($D51,Sheet5!$A$2:$S$73,18,0),"") -> 0 | R51: =IFERROR(VLOOKUP($D51,Sheet5!$A$167:$F$210,5,0),0) -> 0 | S51: =IFERROR(Q51/(R51*20),) -> 0 | T51: =IFERROR(VLOOKUP($D51,Sheet5!$A$2:$S$73,19,0),"") -> 0 | U51: =IFERROR(VLOOKUP($D51,Sheet5!$A$167:$F$200,6,0),0) -> 0 | V51: =IFERROR(T51/(U51*20),) -> 0 | W51: =IFERROR((J51*I51+M51*L51+P51*O51+S51*R51+V51*U51)/SUM(I51,L51,O51,R51,U51),0) -> 0.59159664
K52: JP KHÁC | Q52: XLDKM
A53: JP Staff
A54: 38 | C54: NGO QUOC BAO | D54: bao.nq@altius-link.com.vn | E54: =IFERROR(VLOOKUP($D54,Sheet5!$A$2:$S$73,15,0),"") -> 24 | F54: =IFERROR(VLOOKUP($D54,Sheet5!$A$74:$B$132,2,0),"") -> 16 | G54: =IFERROR(IF((E54-F54)<0,0,(E54-F54)),"") -> 8 | H54: =IFERROR(F54*1.5+G54,"") -> 32 | I54: =IFERROR(VLOOKUP($D54,Sheet5!$A$167:$F$221,2,0),0) -> 2 | J54: =IFERROR(H54/(I54*10),) -> 1.6 | K54: =IFERROR(VLOOKUP($D54,Sheet5!$A$3:$U$33,21,0),"") -> 26 | L54: =IFERROR(VLOOKUP($D54,Sheet5!$A$167:$F$221,3,0),0) -> 4 | M54: =IFERROR(K54/(L54*10),0) -> 0.65 | N54: =IFERROR(VLOOKUP($D54,Sheet5!$A$2:$S$71,17,0),"") -> 21 | O54: =IFERROR(VLOOKUP($D54,Sheet5!$A$167:$F$221,4,0),0) -> 1 | P54: =IFERROR(N54/(O54*10),) -> 2.1 | Q54: =IFERROR(VLOOKUP($D54,Sheet5!$A$2:$W$73,20,0),"") -> 0 | R54: =IFERROR(VLOOKUP($D54,Sheet5!$A$167:$F$210,5,0),0) -> 0 | S54: =IFERROR(Q54/(R54*15),0) -> 0 | T54: =IFERROR(VLOOKUP($D54,Sheet5!$A$2:$S$73,19,0),"") -> 0 | U54: =IFERROR(VLOOKUP($D54,Sheet5!$A$167:$F$200,6,0),0) -> 0 | V54: =IFERROR(T54/(U54*20),) -> 0 | W54: =IFERROR((J54*I54+M54*L54+P54*O54+S54*R54+V54*U54)/SUM(I54,L54,O54,R54,U54),0) -> 1.1285714
E55: =SUM(E15:E54) -> 1515 | F55: =SUM(F15:F54) -> 398 | I55: =SUM(I15:I54) -> 116.94118 | K55: =SUM(K15:K51) -> 0 | L55: =SUM(L15:L54) -> 4 | N55: =SUM(N15:N54) -> 628 | O55: =SUM(O15:O54) -> 32.059902 | Q55: =SUM(Q15:Q51) -> 5 | R55: =SUM(R15:R51) -> 0.25 | T55: =SUM(T15:T53) -> 0 | U55: =SUM(U15:U54) -> 0

Sheet Sheet5
A1: Date/日付 | B1: (All)
A2: 1 | B2: =A2+1 -> 2 | C2: =B2+1 -> 3 | D2: =C2+1 -> 4 | E2: =D2+1 -> 5 | F2: =E2+1 -> 6 | G2: =F2+1 -> 7 | H2: =G2+1 -> 8 | I2: =H2+1 -> 9 | ... AE2: =AD2+1 -> 31
A3: Count of CHANNEL/連絡チャネル | B3: Column Labels
A4: Row Labels | B4: CHAT BOT | C4: Tel/Hotline | D4: Xử lý case (BO Team) | E4: Zalo T | F4: Zalo L | G4: Trả lời Comment | H4: JP khác | I4: Grand Total | O4: HTKH | P4: OB | Q4: case | R4: CMT | S4: DKM | T4: XL DKM | U4: JP KHAC | V4: setsumekai
A5: thang.nt@altius-link.com.vn | B5: 70 | D5: 5 | I5: 75 | O5: =I5-P5-Q5-R5-S5-T5-U5+V5 -> 70 | Q5: =D5 -> 5 | R5: =G5 -> 0 | U5: =H5 -> 0
A6: van.vth1@altius-link.com.vn | B6: 209 | C6: 1 | I6: 210 | O6: =I6-P6-Q6-R6-S6-T6-U6+V6 -> 210 | Q6: =D6 -> 0 | R6: =G6 -> 0 | U6: =H6 -> 0
A7: thuy.ln@altius-link.com.vn | B7: 81 | D7: 32 | I7: 113 | O7: =I7-P7-Q7-R7-S7-T7-U7+V7 -> 81 | Q7: =D7 -> 32 | R7: =G7 -> 0 | U7: =H7 -> 0
A8: huong.pl@altius-link.com.vn | B8: 60 | D8: 35 | I8: 95 | O8: =I8-P8-Q8-R8-S8-T8-U8+V8 -> 60 | Q8: =D8 -> 35 | R8: =G8 -> 0 | U8: =H8 -> 0
A9: cuc.ht@altius-link.com.vn | B9: 61 | D9: 24 | I9: 85 | O9: =I9-P9-Q9-R9-S9-T9-U9+V9 -> 61 | Q9: =D9 -> 24 | R9: =G9 -> 0 | U9: =H9 -> 0
A10: thai.nq@altius-link.com.vn | B10: 49 | D10: 54 | I10: 103 | O10: =I10-P10-Q10-R10-S10-T10-U10+V10 -> 49 | Q10: =D10 -> 54 | R10: =G10 -> 0 | U10: =H10 -> 0
A11: thuy.ntt1@altius-link.com.vn | B11: 55 | D11: 26 | I11: 81 | O11: =I11-P11-Q11-R11-S11-T11-U11+V11 -> 55 | Q11: =D11 -> 26 | R11: =G11 -> 0 | U11: =H11 -> 0
A12: bich.dt@altius-link.com.vn | B12: 101 | D12: 8 | I12: 109 | O12: =I12-P12-Q12-R12-S12-T12-U12+V12 -> 101 | Q12: =D12 -> 8 | R12: =G12 -> 0 | U12: =H12 -> 0
A13: thu.ntn@altius-link.com.vn | B13: 48 | C13: 2 | D13: 10 | F13: 1 | I13: 61 | O13: =I13-P13-Q13-R13-S13-T13-U13+V13 -> 51 | Q13: =D13 -> 10 | R13: =G13 -> 0 | U13: =H13 -> 0
A14: phong.ht@altius-link.com.vn | B14: 40 | D14: 40 | G14: 5 | I14: 85 | O14: =I14-P14-Q14-R14-S14-T14-U14+V14 -> 40 | Q14: =D14 -> 40 | R14: =G14 -> 5 | U14: =H14 -> 0
A15: trang.nt@altius-link.com.vn | B15: 66 | D15: 70 | I15: 136 | O15: =I15-P15-Q15-R15-S15-T15-U15+V15 -> 66 | Q15: =D15 -> 70 | R15: =G15 -> 0 | U15: =H15 -> 0
A16: linh.btk@altius-link.com.vn | B16: 53 | D16: 11 | F16: 5 | I16: 69 | O16: =I16-P16-Q16-R16-S16-T16-U16+V16 -> 58 | Q16: =D16 -> 11 | R16: =G16 -> 0 | U16: =H16 -> 0
A17: thao.tp@altius-link.com.vn | B17: 62 | D17: 75 | E17: 12 | I17: 149 | O17: =I17-P17-Q17-R17-S17-T17-U17+V17 -> 74 | Q17: =D17 -> 75 | R17: =G17 -> 0 | U17: =H17 -> 0
A18: quang.ln@altius-link.com.vn | B18: 10 | I18: 10 | O18: =I18-P18-Q18-R18-S18-T18-U18+V18 -> 10 | Q18: =D18 -> 0 | R18: =G18 -> 0 | U18: =H18 -> 0
A19: duong.tt@altius-link.com.vn | B19: 82 | D19: 48 | I19: 130 | O19: =I19-P19-Q19-R19-S19-T19-U19+V19 -> 82 | Q19: =D19 -> 48 | R19: =G19 -> 0 | U19: =H19 -> 0
A20: anh.bn1@altius-link.com.vn | B20: 57 | D20: 17 | I20: 74 | O20: =I20-P20-Q20-R20-S20-T20-U20+V20 -> 57 | Q20: =D20 -> 17 | R20: =G20 -> 0 | U20: =H20 -> 0
A21: hoai.ptt@altius-link.vn | B21: 11 | I21: 11 | O21: =I21-P21-Q21-R21-S21-T21-U21+V21 -> 11 | Q21: =D21 -> 0 | R21: =G21 -> 0 | U21: =H21 -> 0
A22: long.thq@altius-link.com.vn | B22: 39 | D22: 15 | I22: 54 | O22: =I22-P22-Q22-R22-S22-T22-U22+V22 -> 39 | Q22: =D22 -> 15 | R22: =G22 -> 0 | U22: =H22 -> 0
A23: bao.nq@altius-link.com.vn | B23: 24 | D23: 21 | H23: 26 | I23: 71 | O23: =I23-P23-Q23-R23-S23-T23-U23+V23 -> 24 | Q23: =D23 -> 21 | R23: =G23 -> 0 | U23: =H23 -> 26
A24: linh.dp1@altius-link.com.vn | B24: 68 | I24: 68 | O24: =I24-P24-Q24-R24-S24-T24-U24+V24 -> 68 | Q24: =D24 -> 0 | R24: =G24 -> 0 | U24: =H24 -> 0
A25: huy.d@altius-link.com.vn | B25: 72 | D25: 16 | I25: 88 | O25: =I25-P25-Q25-R25-S25-T25-U25+V25 -> 72 | Q25: =D25 -> 16 | R25: =G25 -> 0 | U25: =H25 -> 0
A26: ly.ntk1@altius-link.com.vn | B26: 23 | I26: 23 | O26: =I26-P26-Q26-R26-S26-T26-U26+V26 -> 23 | Q26: =D26 -> 0 | R26: =G26 -> 0 | U26: =H26 -> 0
A27: anh.np@altius-link.com.vn | B27: 58 | D27: 62 | I27: 120 | O27: =I27-P27-Q27-R27-S27-T27-U27+V27 -> 58 | Q27: =D27 -> 62 | R27: =G27 -> 0 | U27: =H27 -> 0
A28: huong.tl@altius-link.com.vn | B28: 53 | D28: 43 | I28: 96 | O28: =I28-P28-Q28-R28-S28-T28-U28+V28 -> 53 | Q28: =D28 -> 43 | R28: =G28 -> 0 | U28: =H28 -> 0
A29: bach.vh@altius-link.com.vn | B29: 42 | D29: 16 | I29: 58 | O29: =I29-P29-Q29-R29-S29-T29-U29+V29 -> 42 | Q29: =D29 -> 16 | R29: =G29 -> 0 | U29: =H29 -> 0
A30: Grand Total | B30: 1494 | C30: 3 | D30: 628 | E30: 12 | F30: 6 | G30: 5 | H30: 26 | I30: 2174 | O30: =I30-P30-Q30-R30-S30-T30-U30+V30 -> 1515 | Q30: =D30 -> 628 | R30: =G30 -> 5 | U30: =H30 -> 26
A72: 案件作成日時 | B72: (All)
A74: Row Labels | B74: Count of Case Status/案件ステータス
A75: bich.dt@altius-link.com.vn | B75: 16
A76: huong.pl@altius-link.com.vn | B76: 26
A77: thu.ntn@altius-link.com.vn | B77: 8
A78: thuy.ln@altius-link.com.vn | B78: 12
A79: thuy.ntt1@altius-link.com.vn | B79: 13
A80: trang.nt@altius-link.com.vn | B80: 27
A81: (blank)
A82: van.vth1@altius-link.com.vn | B82: 12 | H82: CHANNEL/連絡チャネル | I82: =GETPIVOTDATA("CHANNEL/連絡チャネル",$A$3,"CHANNEL/連絡チャネル","CHAT BOT") -> 1494
...

Sheet 1. CSKH
A1: SBIR REPORT_BÁO CÁO PHIÊN HỖ TRỢ TRONG LIVE SUPPORT | G1: Channel | H1: Customer | I1: Sender_ID = Contact Info
A2: Month | B2: 46298 | G2: Zalo/Viber/Line | H2: =sender ID | I2: Tên ID của KH
G3: Tel | H3: Tên KH | I3: Số điện thoại
G4: Xử lý case (BO Team) | H4: Tên KH trên SF | I4: Mã case
G5: Trả lời Comment | I5: Facebook name _ Facebook ID
G6: Outbound | I6: Facebook name _ Facebook ID
G7: Outbound Reply | I7: Facebook name _ Facebook ID
A9: No/順序数 | B9: Date/日付 | C9: CHANNEL/連絡チャネル | D9: Customer/顧客 | E9: Supporter/サポーター | F9: Start Time/始まる時間 | G9: End Time/終了時間 | H9: Request Description/リクエストの説明 | I9: Session Note/セッションノート | J9: Topic Level 1/トピックレベル | K9: sender_id/連絡先 | L9: ma_kh/顧客コード | M9: DETAIL of Outbound Reply/アウトバウンド返信の詳細 | N9: TEAM
A10: Số thứ tự | B10: Ngày đã hỗ trợ | C10: Zalo/Viber/Line Tel Xử lý case (BO Team) | D10: Tên ID của KH Tel/Xử lý case (BO Team): Tên Khách hàng | E10: Email của OP hỗ trợ | H10: Ghi chú tình trạng hỗ trợ KH -OK: hỗ trợ hoàn thiện - CHƯA: hỗ trợ chưa hoàn thiện Lưu ý: ghi rõ lý do vì sao chưa. Ví dụ: CHƯA (Chờ thẻ nk rõ nét) | I10: ghi chú tình trạng OUTBOUND (nếu có) | J10: Chủ đề mà OP đã hỗ trợ kh, lựa chọn chính xác từ 1-12 | K10: Lưu thông tin để có thể tìm kiếm được KH: mã sender ID trong live support, số điện thoại KH gọi điện đến, tên zalo, viber, line của KH… | L10: Mã khách hàng. (ĐIỀN NẾU CÓ) | M10: ĐIỀN NẾU ở CUSTOMER chọn Outbound Reply
A11: 1 | B11: 46298 | C11: CHAT BOT | D11: Hoa Phu Dung | E11: quang.ln@altius-link.com.vn | F11: 2026-10-03 17:19:30+07:00 | G11: 2026-10-03 19:08:15+07:00 | H11: OK | J11: 11. Gặp nhân viên SBI/オペレーターに問い合わせ | K11: 26056754090601079 | L11: A0011570917
A12: 2 | B12: 46298 | C12: CHAT BOT | D12: Thu Hằngg | E12: huong.tl@altius-link.com.vn | F12: 2026-10-03 16:23:53+07:00 | G12: 2026-10-03 19:07:43+07:00 | H12: Chưa (chưa phản hồi ) | J12: 1. Đăng ký mới/新規登録 | K12: 28225682273769238
A13: 3 | B13: 46298 | C13: CHAT BOT | D13: Rin Sophie | E13: huong.tl@altius-link.com.vn | F13: 2026-10-03 15:17:53+07:00 | G13: 2026-10-03 19:07:22+07:00 | H13: ok | J13: 11. Gặp nhân viên SBI/オペレーターに問い合わせ | K13: 6110307375682227 | L13: A0011023185
A14: 4 | B14: 46298 | C14: CHAT BOT | D14: Nguyễn Anh Quang | E14: quang.ln@altius-link.com.vn | F14: 2026-10-02 19:37:14+07:00 | G14: 2026-10-03 19:07:16+07:00 | H14: Chưa (chưa phản hồi ) | J14: 3. Tình trạng thẻ/カード発送状況 | K14: 25740190738971895 | L14: A0011519430
A15: 5 | B15: 46298 | C15: CHAT BOT | D15: Linh Capuchino's | E15: huong.tl@altius-link.com.vn | F15: 2026-10-03 15:08:42+07:00 | G15: 2026-10-03 19:07:06+07:00 | H15: ok | J15: 9. Giấy CNCT/送金明細書 | K15: 1925211284263245 | L15: A0010407248
A16: 6 | B16: 46298 | C16: CHAT BOT | D16: Yến Nguyễn | E16: quang.ln@altius-link.com.vn | F16: 2026-10-02 19:41:28+07:00 | G16: 2026-10-03 19:07:06+07:00 | H16: Chưa (chưa phản hồi ) | J16: 11. Gặp nhân viên SBI/オペレーターに問い合わせ | K16: 7363829280313140 | L16: A0010802913
A17: 7 | B17: 46298 | C17: CHAT BOT | D17: Công Thành | E17: huong.tl@altius-link.com.vn | F17: 2026-10-03 15:40:41+07:00 | G17: 2026-10-03 19:06:48+07:00 | H17: Chưa (Chờ KH phản hồi) | J17: 9. Giấy CNCT/送金明細書 | K17: 4457172804303296 | L17: A0010871045
A18: 8 | B18: 46298 | C18: CHAT BOT | D18: Nguyễn Văn Tuấn | E18: huong.tl@altius-link.com.vn | F18: 2026-10-03 15:20:10+07:00 | G18: 2026-10-03 19:06:26+07:00 | H18: ok | J18: 11. Gặp nhân viên SBI/オペレーターに問い合わせ | K18: 38021719117475110 | L18: A0010841334
A19: 9 | B19: 46298 | C19: CHAT BOT | D19: Luan Pham | E19: bich.dt@altius-link.com.vn | F19: 2026-10-03 17:11:20+07:00 | G19: 2026-10-03 19:06:22+07:00 | H19: chưa | J19: 6. Tình trạng giao dịch/取引状況 | K19: 9921253781228052 | L19: A0010656091
A20: 10 | B20: 46298 | C20: CHAT BOT | D20: Nguyễn Bắc | E20: huong.tl@altius-link.com.vn | F20: 2026-10-03 14:54:41+07:00 | G20: 2026-10-03 19:06:09+07:00 | H20: ok | J20: 11. Gặp nhân viên SBI/オペレーターに問い合わせ | K20: 3343816568996810 | L20: A0010631006
A21: 11 | B21: 46298 | C21: CHAT BOT | D21: Hồng Thoan Phạm | E21: quang.ln@altius-link.com.vn | F21: 2026-10-03 18:29:12+07:00 | G21: 2026-10-03 19:06:02+07:00 | H21: Chưa (hết ca) | J21: 2. Thêm người nhận/受取人追加登録 | K21: 24382439591352588 | L21: A0011471294
A22: 12 | B22: 46298 | C22: CHAT BOT | D22: Trưởng Phạm | E22: quang.ln@altius-link.com.vn | F22: 2026-10-03 18:39:28+07:00 | G22: 2026-10-03 19:05:47+07:00 | H22: Chưa (Chờ KH phản hồi) | J22: 3. Tình trạng thẻ/カード発送状況 | K22: 29730427963223569
A23: 13 | B23: 46298 | C23: CHAT BOT | D23: Kim Oanh | E23: huong.tl@altius-link.com.vn | F23: 2026-10-03 14:41:52+07:00 | G23: 2026-10-03 19:05:43+07:00 | H23: ok | J23: 3. Tình trạng thẻ/カード発送状況 | K23: 6438984282782997 | L23: A0011007173
A24: 14 | B24: 46298 | C24: CHAT BOT | D24: Lê Vân Annh | E24: bao.nq@altius-link.com.vn | F24: 2026-10-03 18:09:29+07:00 | G24: 2026-10-03 19:05:35+07:00 | H24: ok | J24: 11. Gặp nhân viên SBI/オペレーターに問い合わせ | K24: 6610754065621793 | L24: A0011137493
A25: 15 | B25: 46298 | C25: CHAT BOT | D25: Hải Đăng | E25: huong.tl@altius-link.com.vn | F25: 2026-10-03 10:49:21+07:00 | G25: 2026-10-03 19:05:27+07:00 | H25: Chưa (Chờ KH phản hồi) | J25: 11. Gặp nhân viên SBI/オペレーターに問い合わせ | K25: 1528869470570914 | L25: A0010251593
A26: 16 | B26: 46298 | C26: CHAT BOT | D26: Nguyễn Văn Bình | E26: huong.tl@altius-link.com.vn | F26: 2026-10-03 13:22:22+07:00 | G26: 2026-10-03 19:05:05+07:00 | H26: ok | J26: 7. Cập nhật thẻ ngoại kiều/在留カード更新 | K26: 4139426872750467 | L26: A0010762385
A27: 17 | B27: 46298 | C27: CHAT BOT | D27: Nguyễn Linh | E27: bao.nq@altius-link.com.vn | F27: 2026-10-03 17:01:09+07:00 | G27: 2026-10-03 19:04:56+07:00 | H27: Chưa (chưa phản hồi ) | J27: 7. Cập nhật thẻ ngoại kiều/在留カード更新 | K27: 25756998880666489
A28: 18 | B28: 46298 | C28: CHAT BOT | D28: Hoàn Nguyễn | E28: hoai.ptt@altius-link.vn | F28: 2026-10-03 18:39:22+07:00 | G28: 2026-10-03 19:04:45+07:00 | H28: Chưa (Chờ KH phản hồi) | J28: 3. Tình trạng thẻ/カード発送状況 | K28: 7890760887660694 | L28: A0010986613
A29: 19 | B29: 46298 | C29: CHAT BOT | D29: Trâmm | E29: huong.tl@altius-link.com.vn | F29: 2026-10-03 11:06:54+07:00 | G29: 2026-10-03 19:04:45+07:00 | H29: Chưa (Chờ KH phản hồi) | J29: 11. Gặp nhân viên SBI/オペレーターに問い合わせ | K29: 28611769175146986 | L29: A0011707815
A30: 20 | B30: 46298 | C30: CHAT BOT | D30: Nguyễn Thành Đạt | E30: bao.nq@altius-link.com.vn | F30: 2026-10-03 15:44:09+07:00 | G30: 2026-10-03 19:04:36+07:00 | H30: ok | J30: 9. Giấy CNCT/送金明細書 | K30: 28304709832518523 | L30: A0011573193
A31: 21 | B31: 46298 | C31: CHAT BOT | D31: Minh Anh | E31: huong.tl@altius-link.com.vn | F31: 2026-10-03 11:06:06+07:00 | G31: 2026-10-03 19:04:30+07:00 | H31: ok | J31: 13. Đăng ký sử dụng APP/アプリ登録 | K31: 6600037433367930 | L31: A0010986283
A32: 22 | B32: 46298 | C32: CHAT BOT | D32: Vũ Như Quỳnh | E32: hoai.ptt@altius-link.vn | F32: 2026-10-03 18:26:24+07:00 | G32: 2026-10-03 19:04:26+07:00 | H32: Chưa (Chờ KH phản hồi) | J32: 3. Tình trạng thẻ/カード発送状況 | K32: 28452950267657322 | L32: A0011670192
A33: 23 | B33: 46298 | C33: CHAT BOT | D33: Tân Nguyễn | E33: hoai.ptt@altius-link.vn | F33: 2026-10-03 18:37:05+07:00 | G33: 2026-10-03 19:04:17+07:00 | H33: Chưa (Chờ KH phản hồi) | J33: 11. Gặp nhân viên SBI/オペレーターに問い合わせ | K33: 24921681084133994 | L33: A0011437909
A34: 24 | B34: 46298 | C34: CHAT BOT | D34: Ngọc Bích | E34: bao.nq@altius-link.com.vn | F34: 2026-10-03 10:30:45+07:00 | G34: 2026-10-03 19:04:15+07:00 | H34: ok | J34: 11. Gặp nhân viên SBI/オペレーターに問い合わせ | K34: 5664630046929741 | L34: A0010605521
A35: 25 | B35: 46298 | C35: CHAT BOT | D35: Nguyễn Công Bảo | E35: huong.tl@altius-link.com.vn | F35: 2026-10-03 11:01:41+07:00 | G35: 2026-10-03 19:04:06+07:00 | H35: Chưa (chưa phản hồi ) | J35: 11. Gặp nhân viên SBI/オペレーターに問い合わせ | K35: 7729590183749137 | L35: A0010986230
A36: 26 | B36: 46298 | C36: CHAT BOT | D36: Văn Vinh | E36: bich.dt@altius-link.com.vn | F36: 2026-10-03 11:47:04+07:00 | G36: 2026-10-03 19:04:03+07:00 | H36: ok | J36: 3. Tình trạng thẻ/カード発送状況 | K36: 25333001206402366 | L36: A0011556514
A37: 27 | B37: 46298 | C37: CHAT BOT | D37: Thanh Tú | E37: huong.tl@altius-link.com.vn | F37: 2026-10-03 17:30:18+07:00 | G37: 2026-10-03 19:03:50+07:00 | H37: ok | J37: 3. Tình trạng thẻ/カード発送状況 | K37: 25740962535495559 | L37: A0011508851
A38: 28 | B38: 46298 | C38: CHAT BOT | D38: Danh Luu | E38: bich.dt@altius-link.com.vn | F38: 2026-10-03 15:15:05+07:00 | G38: 2026-10-03 19:03:46+07:00 | H38: ok | J38: 3. Tình trạng thẻ/カード発送状況 | K38: 4988075234597001 | L38: A0010657013
A39: 29 | B39: 46298 | C39: CHAT BOT | D39: Vu Duy Thanh | E39: bich.dt@altius-link.com.vn | F39: 2026-10-03 15:07:57+07:00 | G39: 2026-10-03 19:03:32+07:00 | H39: ok | J39: 2. Thêm người nhận/受取人追加登録 | K39: 7224350684286454 | L39: A0011131718
... A90: 80 | B90: 46298 | C90: CHAT BOT | D90: Thuy Hùng | E90: thuy.ntt1@altius-link.com.vn | F90: 2026-10-03 13:47:13+07:00 | G90: 2026-10-03 18:58:25+07:00 | H90: ok | J90: 11. Gặp nhân viên SBI/オペレーターに問い合わせ | K90: 4735269896534639 | L90: A0010602357
A91: 81 | B91: 46298 | C91: CHAT BOT | D91: Nguyễn Thị Thu Trang | E91: thuy.ntt1@altius-link.com.vn | F91: 2026-10-03 14:00:02+07:00 | G91: 2026-10-03 18:58:18+07:00 | H91: ok | J91: 9. Giấy CNCT/送金明細書 | K91: 39463370289920789
...

Sheet 2. SF Case info
B2: SF CASE REPORT
B3: 46298
B6: Case information/案件情報: Case Number/案件番号 | C6: Customer information/顧客情報:取引先名 | D6: Case Status/案件ステータス | E6: 案件作成日時 | F6: Requested By/案件登録者 | G6: Supporter email | H6: Date
B7: 20261012157866 | C7: DANG HANH NGUYEN KIM | D7: Complete/完了 | E7: 2026/10/03 11:12 | F7: VU THI HONG VAN | G7: =VLOOKUP($F7,'mail SF'!$C$3:$D$69,2,0) -> van.vth1@altius-link.com.vn | H7: 46298
B8: 20261012157878 | C8: NGUYEN MANH HUNG | D8: Complete/完了 | E8: 2026/10/03 11:17 | F8: VU THI HONG VAN | G8: =VLOOKUP($F8,'mail SF'!$C$3:$D$69,2,0) -> van.vth1@altius-link.com.vn | H8: 46298
B9: 20261012157914 | C9: NGUYEN HUONG THI THANH | D9: Processing request/処理依頼 | E9: 2026/10/03 11:29 | F9: VU THI HONG VAN | G9: =VLOOKUP($F9,'mail SF'!$C$3:$D$69,2,0) -> van.vth1@altius-link.com.vn | H9: 46298
B10: 20261012157919 | C10: NGUYEN HUONG THI THANH | D10: Complete/完了 | E10: 2026/10/03 11:31 | F10: VU THI HONG VAN | G10: =VLOOKUP($F10,'mail SF'!$C$3:$D$69,2,0) -> van.vth1@altius-link.com.vn | H10: 46298
B11: 20261012157964 | C11: PHAM QUYNH HAU | D11: Complete/完了 | E11: 2026/10/03 11:45 | F11: Nguyen Thi Ngoc Thu | G11: =VLOOKUP($F11,'mail SF'!$C$3:$D$69,2,0) -> thu.ntn@altius-link.com.vn | H11: 46298
B12: 20261012157989 | C12: NGUYEN THI MAI CHI | D12: Complete/完了 | E12: 2026/10/03 11:57 | F12: Nguyen Thi Ngoc Thu | G12: =VLOOKUP($F12,'mail SF'!$C$3:$D$69,2,0) -> thu.ntn@altius-link.com.vn | H12: 46298
B13: 20261012157991 | C13: NGUYEN THI KIEU VAN | D13: Complete/完了 | E13: 2026/10/03 11:58 | F13: DUONG HUY | G13: =VLOOKUP($F13,'mail SF'!$C$3:$D$69,2,0) -> huy.d@altius-link.com.vn | H13: 46298
B14: 20261012157992 | C14: HOANG THI THAO | D14: Complete/完了 | E14: 2026/10/03 11:58 | F14: NGO QUOC BAO | G14: =VLOOKUP($F14,'mail SF'!$C$3:$D$69,2,0) -> bao.nq@altius-link.com.vn | H14: 46298
B15: 20261012157993 | C15: DANG VAN VAN | D15: Complete/完了 | E15: 2026/10/03 11:59 | F15: Le Ngoc Thuy | G15: =VLOOKUP($F15,'mail SF'!$C$3:$D$69,2,0) -> thuy.ln@altius-link.com.vn | H15: 46298
B16: 20261012157995 | C16: HA THI NGOC | D16: Complete/完了 | E16: 2026/10/03 11:59 | F16: DUONG HUY | G16: =VLOOKUP($F16,'mail SF'!$C$3:$D$69,2,0) -> huy.d@altius-link.com.vn | H16: 46298
B17: 20261012158003 | C17: LE THI THIET | D17: Processing request/処理依頼 | E17: 2026/10/03 12:02 | F17: BUI NGOC ANH | G17: =VLOOKUP($F17,'mail SF'!$C$3:$D$69,2,0) -> anh.bn1@altius-link.com.vn | H17: 46298
B18: 20261012158007 | C18: NGUYEN VIET XUAN | D18: Complete/完了 | E18: 2026/10/03 12:04 | F18: BUI NGOC ANH | G18: =VLOOKUP($F18,'mail SF'!$C$3:$D$69,2,0) -> anh.bn1@altius-link.com.vn | H18: 46298
... B404: 20261012160205 | C404: BUI CHI TRUONG | D404: Complete/完了 | E404: 2026/10/03 21:05 | F404: LUU NGOC QUANG | G404: =VLOOKUP($F404,'mail SF'!$C$3:$D$69,2,0) -> quang.ln@altius-link.com.vn | H404: 46298

Sheet 3. Other Tasks & Working time
B1: SBIR REPORT_Others
B2: Date: | C2: 46298
B5: NO. | C5: DATE | D5: TEAM | E5: Supporter Email | F5: TỔNG GIỜ LÀM | G5: Tổng số giờ đã hỗ trợ KH (Lập Case+Không lập Case) | H5: Tổng số giờ đã Outbound | I5: Tổng số giờ đã xử lý case | J5: Trả lời Comment | K5: Đăng ký mới + webform + Gọi OB | L5: Khác
C6: 46298 | E6: anh.bn1@altius-link.com.vn | F6: =SUM(G6:M13) -> 4 | G6: 3 | I6: 1 | L6: Đăng tỷ giá, Đăng bài
C7: 46298 | E7: anh.bn1@altius-link.com.vn | L7: Setsumekai
C8: 46298 | E8: anh.bn1@altius-link.com.vn | L8: Họp team
C9: 46298 | E9: anh.bn1@altius-link.com.vn | L9: Hỗ trợ khác
C10: 46298 | E10: anh.bn1@altius-link.com.vn | L10: Làm báo cáo
C11: 46298 | E11: anh.bn1@altius-link.com.vn | L11: Đào tạo
C12: 46298 | E12: anh.bn1@altius-link.com.vn | L12: Follow/Quản lý team
C13: 46298 | E13: anh.bn1@altius-link.com.vn | L13: Khác
C14: 46298 | E14: thu.ntn@altius-link.com.vn | F14: =SUM(G14:M21) -> 4 | G14: 3 | I14: 0.5 | L14: Đăng tỷ giá, Đăng bài
C15: 46298 | E15: thu.ntn@altius-link.com.vn | L15: Setsumekai
C16: 46298 | E16: thu.ntn@altius-link.com.vn | L16: Họp team
C17: 46298 | E17: thu.ntn@altius-link.com.vn | L17: Hỗ trợ khác
C18: 46298 | E18: thu.ntn@altius-link.com.vn | L18: Làm báo cáo
C19: 46298 | E19: thu.ntn@altius-link.com.vn | L19: Đào tạo
C20: 46298 | E20: thu.ntn@altius-link.com.vn | L20: Follow/Quản lý team
C21: 46298 | E21: thu.ntn@altius-link.com.vn | L21: Khác | M21: 0.5
C22: 46298 | E22: duong.tt@altius-link.com.vn | F22: =SUM(G22:M29) -> 8 | G22: 4.5 | I22: 2.5 | L22: Đăng tỷ giá, Đăng bài
C23: 46298 | E23: duong.tt@altius-link.com.vn | L23: Setsumekai
C24: 46298 | E24: duong.tt@altius-link.com.vn | L24: Họp team
C25: 46298 | E25: duong.tt@altius-link.com.vn | L25: Hỗ trợ khác
C26: 46298 | E26: duong.tt@altius-link.com.vn | L26: Làm báo cáo
C27: 46298 | E27: duong.tt@altius-link.com.vn | L27: Đào tạo
C28: 46298 | E28: duong.tt@altius-link.com.vn | L28: Follow/Quản lý team
C29: 46298 | E29: duong.tt@altius-link.com.vn | L29: Khác | M29: 1
C30: 46298 | E30: phong.ht@altius-link.com.vn | F30: =SUM(G30:M37) -> 8 | G30: 4.75 | I30: 2 | J30: 0.25 | L30: Đăng tỷ giá, Đăng bài
C31: 46298 | E31: phong.ht@altius-link.com.vn | L31: Setsumekai
C32: 46298 | E32: phong.ht@altius-link.com.vn | L32: Họp team
C33: 46298 | E33: phong.ht@altius-link.com.vn | L33: Hỗ trợ khác
C34: 46298 | E34: phong.ht@altius-link.com.vn | L34: Làm báo cáo
C35: 46298 | E35: phong.ht@altius-link.com.vn | L35: Đào tạo
C36: 46298 | E36: phong.ht@altius-link.com.vn | L36: Follow/Quản lý team
C37: 46298 | E37: phong.ht@altius-link.com.vn | L37: Khác | M37: 1
C38: 46298 | E38: thai.nq@altius-link.com.vn | F38: =SUM(G38:M45) -> 8 | G38: 6 | I38: 1 | L38: Đăng tỷ giá, Đăng bài
C39: 46298 | E39: thai.nq@altius-link.com.vn | L39: Setsumekai
C40: 46298 | E40: thai.nq@altius-link.com.vn | L40: Họp team
C41: 46298 | E41: thai.nq@altius-link.com.vn | L41: Hỗ trợ khác
C42: 46298 | E42: thai.nq@altius-link.com.vn | L42: Làm báo cáo
...

Sheet 4.CSKH(送金状況確認)
A1: SBIR REPORT_BÁO CÁO PHIÊN HỖ TRỢ TRONG LIVE SUPPORT | G1: Channel | H1: Customer | I1: Sender_ID = Contact Info
A2: Month | B2: 45297 | G2: Zalo/Viber/Line | H2: =sender ID | I2: Tên ID của KH
G3: Tel | H3: Tên KH | I3: Số điện thoại
G4: Xử lý case (BO Team) | H4: Tên KH trên SF | I4: Mã case
G5: Facebook Comment | I5: Facebook name _ Facebook ID
G6: Outbound | I6: Facebook name _ Facebook ID
G7: Outbound Reply | I7: Facebook name _ Facebook ID
A9: No/順序数 | B9: Date/日付 | C9: CHANNEL/連絡チャネル | D9: Customer/顧客 | E9: Supporter/サポーター | F9: Start Time/始まる時間 | G9: End Time/終了時間 | H9: Request Description/リクエストの説明 | I9: Session Note/セッションノート | J9: Topic Level 1/トピックレベル | K9: sender_id/連絡先 | L9: ma_kh/顧客コード | M9: DETAIL of Outbound Reply/アウトバウンド返信の詳細 | N9: TEAM
A10: Số thứ tự | B10: Ngày đã hỗ trợ | C10: Zalo/Viber/Line Tel Xử lý case (BO Team) | D10: Tên ID của KH Tel/Xử lý case (BO Team): Tên Khách hàng | E10: Email của OP hỗ trợ | H10: Ghi chú tình trạng hỗ trợ KH -OK: hỗ trợ hoàn thiện - CHƯA: hỗ trợ chưa hoàn thiện Lưu ý: ghi rõ lý do vì sao chưa. Ví dụ: CHƯA (Chờ thẻ nk rõ nét) | I10: ghi chú tình trạng OUTBOUND (nếu có) | J10: Chủ đề mà OP đã hỗ trợ kh, lựa chọn chính xác từ 1-12 | K10: Lưu thông tin để có thể tìm kiếm được KH: mã sender ID trong live support, số điện thoại KH gọi điện đến, tên zalo, viber, line của KH… | L10: Mã khách hàng. (ĐIỀN NẾU CÓ) | M10: ĐIỀN NẾU ở CUSTOMER chọn Outbound Reply
A11: 1 | B11: 45297 | C11: CHAT BOT | D11: Puka Nga | E11: hoai.ptt@relia-vietnam.com.vn | F11: 2024-01-05 16:32:15+07:00 | G11: 2024-01-06 19:38:10+07:00 | H11: Chờ KH phản hồi | J11: 9. Giấy CNCT/送金明細書 | K11: 7266812570016396 | L11: A0011152817
A12: 2 | B12: 45297 | C12: CHAT BOT | D12: Hieu Nguyen | E12: hoai.ptt@relia-vietnam.com.vn | F12: 2024-01-06 19:24:31+07:00 | G12: 2024-01-06 19:31:54+07:00 | H12: Chờ KH phản hồi | J12: 9. Giấy CNCT/送金明細書 | K12: 6664775266883008 | L12: A0010580324
A13: 3 | B13: 45297 | C13: CHAT BOT | D13: Phuong Nguyen | E13: linh.ptk@relia-vietnam.com.vn | F13: 2024-01-06 19:24:25+07:00 | G13: 2024-01-06 19:28:11+07:00 | H13: ok | J13: 5. Đổi thông tin thẻ/カード情報変更 | K13: 2180319332043764 | L13: A0010431440
A14: 4 | B14: 45297 | C14: CHAT BOT | D14: Thuỳ Hương | E14: luyen.lt@relia-vietnam.com.vn | F14: 2024-01-06 17:42:05+07:00 | G14: 2024-01-06 19:25:58+07:00 | H14: ok | J14: 5. Đổi thông tin thẻ/カード情報変更 | K14: 5387867797978271 | L14: A0011020371
A15: 5 | B15: 45297 | C15: CHAT BOT | D15: Hanh Phuc Moi Ngay | E15: luyen.lt@relia-vietnam.com.vn | F15: 2024-01-04 11:06:07+07:00 | G15: 2024-01-06 19:25:13+07:00 | H15: Chưa (hết ca) | J15: 6. Tình trạng giao dịch/取引状況 | K15: 3442601625762487 | L15: a0010760871
A16: 6 | B16: 45297 | C16: CHAT BOT | D16: Phuong Nguyen | E16: linh.ptk@relia-vietnam.com.vn | F16: 2024-01-05 19:28:17+07:00 | G16: 2024-01-06 19:24:25+07:00 | H16: Chưa (hết ca) | J16: 5. Đổi thông tin thẻ/カード情報変更 | K16: 2180319332043764 | L16: A0010431440
A17: 7 | B17: 45297 | C17: CHAT BOT | D17: Quốc Toản | E17: luyen.lt@relia-vietnam.com.vn | F17: 2024-01-05 20:05:16+07:00 | G17: 2024-01-06 19:22:32+07:00 | H17: okk | J17: 9. Giấy CNCT/送金明細書 | K17: 2580887972016927 | L17: A0010799767
A18: 8 | B18: 45297 | C18: CHAT BOT | D18: Xóa | E18: linh.ptk@relia-vietnam.com.vn | F18: 2024-01-06 17:05:32+07:00 | G18: 2024-01-06 19:17:37+07:00 | H18: ok | J18: 7. Cập nhật thẻ ngoại kiều/在留カード更新 | K18: 5917251695006434 | L18: A0010567296
A19: 9 | B19: 45297 | C19: CHAT BOT | D19: Cao Hiện Shiga | E19: linh.ptk@relia-vietnam.com.vn | F19: 2024-01-05 19:26:39+07:00 | G19: 2024-01-06 19:14:51+07:00 | H19: ok | J19: 5. Đổi thông tin thẻ/カード情報変更 | K19: 1191648600937392 | L19: A0010379190
A20: 10 | B20: 45297 | C20: CHAT BOT | D20: Phuong Nguyen | E20: luyen.lt@relia-vietnam.com.vn | F20: 2024-01-02 17:33:13+07:00 | G20: 2024-01-06 19:14:34+07:00 | H20: ok | J20: 6. Tình trạng giao dịch/取引状況 | K20: 2033087050059842 | L20: A0010417979
A21: 11 | B21: 45297 | C21: CHAT BOT | D21: Nguyễn Cường | E21: linh.ptk@relia-vietnam.com.vn | F21: 2024-01-05 19:26:07+07:00 | G21: 2024-01-06 19:14:14+07:00 | H21: Chưa (hết ca) | J21: 11. Gặp nhân viên SBI/オペレーターに問い合わせ | K21: 6932044270215027
A22: 12 | B22: 45297 | C22: CHAT BOT | D22: Nguyễn Thu Hằng | E22: luyen.lt@relia-vietnam.com.vn | F22: 2024-01-04 17:50:29+07:00 | G22: 2024-01-06 19:14:00+07:00 | H22: ok | J22: 6. Tình trạng giao dịch/取引状況 | K22: 24594465710199985 | L22: a0011062256
A23: 13 | B23: 45297 | C23: CHAT BOT | D23: Thanh Trúc | E23: linh.ptk@relia-vietnam.com.vn | F23: 2024-01-05 19:25:30+07:00 | G23: 2024-01-06 19:13:38+07:00 | H23: ok | J23: 11. Gặp nhân viên SBI/オペレーターに問い合わせ | K23: 6064064916950990 | L23: A0010930890
A24: 14 | B24: 45297 | C24: CHAT BOT | D24: Hoa Duong | E24: luyen.lt@relia-vietnam.com.vn | F24: 2024-01-04 20:12:24+07:00 | G24: 2024-01-06 19:13:18+07:00 | H24: ok | J24: 9. Giấy CNCT/送金明細書 | K24: 3810769889025227 | L24: A0010720997
A25: 15 | B25: 45297 | C25: CHAT BOT | D25: Bống Phạm | E25: cuc.ptk@relia-vietnam.com.vn | F25: 2024-01-06 18:04:05+07:00 | G25: 2024-01-06 19:13:03+07:00 | H25: OK | J25: 11. Gặp nhân viên SBI/オペレーターに問い合わせ | K25: 6892809130815161
A26: 16 | B26: 45297 | C26: CHAT BOT | D26: Lê Sỹ Quỳnh | E26: luyen.lt@relia-vietnam.com.vn | F26: 2024-01-05 18:20:03+07:00 | G26: 2024-01-06 19:12:43+07:00 | H26: Chưa (hết ca) | J26: 1. Đăng ký mới/新規登録 | K26: 7351213918264362 | L26: A0011193067
A27: 17 | B27: 45297 | C27: CHAT BOT | D27: 吉田洋美 | E27: luyen.lt@relia-vietnam.com.vn | F27: 2024-01-05 19:41:14+07:00 | G27: 2024-01-06 19:11:03+07:00 | H27: Chưa (hết ca) | J27: 2. Thêm người nhận/受取人追加登録 | K27: 23999398893008968 | L27: A0010971041
A28: 18 | B28: 45297 | C28: CHAT BOT | D28: Tú Yên | E28: linh.ptk@relia-vietnam.com.vn | F28: 2024-01-06 19:10:08+07:00 | G28: 2024-01-06 19:11:00+07:00 | H28: Chưa (hết ca) | J28: 5. Đổi thông tin thẻ/カード情報変更 | K28: 6034542846663674 | L28: A0011043700
A29: 19 | B29: 45297 | C29: CHAT BOT | D29: Lê Duy Tùng | E29: luyen.lt@relia-vietnam.com.vn | F29: 2024-01-05 20:16:22+07:00 | G29: 2024-01-06 19:10:37+07:00 | H29: Chưa (hết ca) | J29: 2. Thêm người nhận/受取人追加登録 | K29: 5598557476833763 | L29: A0010941883
A30: 20 | B30: 45297 | C30: CHAT BOT | D30: Hoàng Thương | E30: luyen.lt@relia-vietnam.com.vn | F30: 2024-01-05 20:31:31+07:00 | G30: 2024-01-06 19:10:17+07:00 | H30: ok | J30: 2. Thêm người nhận/受取人追加登録 | K30: 24341442188835777 | L30: A0010676268
A31: 21 | B31: 45297 | C31: CHAT BOT | D31: Tú Yên | E31: linh.ptk@relia-vietnam.com.vn | F31: 2024-01-05 19:12:32+07:00 | G31: 2024-01-06 19:10:08+07:00 | H31: OK | J31: 2. Thêm người nhận/受取人追加登録 | K31: 6034542846663674 | L31: A0011043700
A32: 22 | B32: 45297 | C32: CHAT BOT | D32: Huế Lê | E32: luyen.lt@relia-vietnam.com.vn | F32: 2024-01-05 20:20:01+07:00 | G32: 2024-01-06 19:09:44+07:00 | H32: Chưa (hết ca) | J32: 2. Thêm người nhận/受取人追加登録 | K32: 1423593094381408
A33: 23 | B33: 45297 | C33: CHAT BOT | D33: Lê Thị Trang | E33: luyen.lt@relia-vietnam.com.vn | F33: 2024-01-05 20:22:23+07:00 | G33: 2024-01-06 19:08:54+07:00 | H33: Chưa (hết ca) | J33: 8. Tỷ giá/Lệ phí/為替レート/手数料 | K33: 6941424805935315 | L33: a0011150597
A34: 24 | B34: 45297 | C34: CHAT BOT | D34: Loan Le | E34: luyen.lt@relia-vietnam.com.vn | F34: 2024-01-03 04:04:57+07:00 | G34: 2024-01-06 19:08:16+07:00 | H34: Chưa (hết ca) | J34: 11. Gặp nhân viên SBI/オペレーターに問い合わせ | K34: 6973767465985146 | L34: A0010576022
A35: 25 | B35: 45297 | C35: CHAT BOT | D35: Linh Bom | E35: luyen.lt@relia-vietnam.com.vn | F35: 2024-01-05 17:45:03+07:00 | G35: 2024-01-06 19:06:36+07:00 | H35: ok | J35: 1. Đăng ký mới/新規登録 | K35: 7100235760019586
A36: 26 | B36: 45297 | C36: CHAT BOT | D36: Đinh Tuyết | E36: luyen.lt@relia-vietnam.com.vn | F36: 2024-01-05 17:22:04+07:00 | G36: 2024-01-06 19:05:22+07:00 | H36: Chưa (hết ca) | J36: 2. Thêm người nhận/受取人追加登録 | K36: 2555738541192221 | L36: A0011068798
A37: 27 | B37: 45297 | C37: CHAT BOT | D37: Kim Ngân | E37: hanh.dth1@relia-vietnam.com.vn | F37: 2024-01-05 19:29:10+07:00 | G37: 2024-01-06 19:05:21+07:00 | H37: chưa(chưa phản hồi) | J37: 13. Đăng ký sử dụng APP/アプリ登録 | K37: 24428496883461023
